---
choices:
  - "It remains open until garbage collected"
  - "It causes a memory leak"
  - "It will automatically rollback the transaction"
answer:
  - "It is closed automatically if try-with-resources is used"
explanation: "If try-with-resources is used, the ResultSet is closed automatically."
---

What happens if an exception is thrown before a `ResultSet` is closed?
